<?xml version="1.0" encoding="utf-8"?>
<!-- This URDF was automatically created by SolidWorks to URDF Exporter! Originally created by Stephen Brawner (brawner@gmail.com) 
     Commit Version: 1.6.0-1-g15f4949  Build Version: 1.6.7594.29634
     For more information, please see http://wiki.ros.org/sw_urdf_exporter -->
<robot
  name="RobotNurse.URDF">
  <link
    name="Base">
    <inertial>
      <origin
        xyz="0.00031875 0.13537 -0.011156"
        rpy="0 0 0" />
      <mass
        value="90.341" />
      <inertia
        ixx="3.5753"
        ixy="-0.0043603"
        ixz="0.0057259"
        iyy="5.7246"
        iyz="0.15261"
        izz="3.2601" />
    </inertial>
    <visual>
      <origin
        xyz="0 0 0"
        rpy="0 0 0" />
      <geometry>
        <mesh
          filename="package://RobotNurse.URDF/meshes/Base.STL" />
      </geometry>
      <material
        name="">
        <color
          rgba="0.50196 0.50196 0.50196 1" />
      </material>
    </visual>
    <collision>
      <origin
        xyz="0 0 0"
        rpy="0 0 0" />
      <geometry>
        <mesh
          filename="package://RobotNurse.URDF/meshes/Base.STL" />
      </geometry>
    </collision>
  </link>
  <link
    name="w1">
    <inertial>
      <origin
        xyz="0.074536 0 0"
        rpy="0 0 0" />
      <mass
        value="6.7775" />
      <inertia
        ixx="0.053219"
        ixy="-7.4745E-35"
        ixz="-1.417E-19"
        iyy="0.03802"
        iyz="-2.9562E-36"
        izz="0.03802" />
    </inertial>
    <visual>
      <origin
        xyz="0 0 0"
        rpy="0 0 0" />
      <geometry>
        <mesh
          filename="package://RobotNurse.URDF/meshes/w1.STL" />
      </geometry>
      <material
        name="">
        <color
          rgba="0.75294 0.75294 0.75294 1" />
      </material>
    </visual>
    <collision>
      <origin
        xyz="0 0 0"
        rpy="0 0 0" />
      <geometry>
        <mesh
          filename="package://RobotNurse.URDF/meshes/w1.STL" />
      </geometry>
    </collision>
  </link>
  <joint
    name="w1"
    type="continuous">
    <origin
      xyz="0.2 -0.25 0.08"
      rpy="1.5707963267949 0 0" />
    <parent
      link="Base" />
    <child
      link="w1" />
    <axis
      xyz="1 0 0" />
  </joint>
  <link
    name="w2">
    <inertial>
      <origin
        xyz="0.074536 0 0"
        rpy="0 0 0" />
      <mass
        value="6.7775" />
      <inertia
        ixx="0.053219"
        ixy="-7.4745E-35"
        ixz="-1.1505E-19"
        iyy="0.03802"
        iyz="-2.9562E-36"
        izz="0.03802" />
    </inertial>
    <visual>
      <origin
        xyz="0 0 0"
        rpy="0 0 0" />
      <geometry>
        <mesh
          filename="package://RobotNurse.URDF/meshes/w2.STL" />
      </geometry>
      <material
        name="">
        <color
          rgba="0.75294 0.75294 0.75294 1" />
      </material>
    </visual>
    <collision>
      <origin
        xyz="0 0 0"
        rpy="0 0 0" />
      <geometry>
        <mesh
          filename="package://RobotNurse.URDF/meshes/w2.STL" />
      </geometry>
    </collision>
  </link>
  <joint
    name="w2"
    type="continuous">
    <origin
      xyz="0.2 0.25 0.08"
      rpy="1.5707963267949 0 0" />
    <parent
      link="Base" />
    <child
      link="w2" />
    <axis
      xyz="1 0 0" />
  </joint>
  <link
    name="w3">
    <inertial>
      <origin
        xyz="0.074536 0 1.3878E-17"
        rpy="0 0 0" />
      <mass
        value="6.7775" />
      <inertia
        ixx="0.053219"
        ixy="-1.3969E-19"
        ixz="9.0744E-21"
        iyy="0.03802"
        iyz="0"
        izz="0.03802" />
    </inertial>
    <visual>
      <origin
        xyz="0 0 0"
        rpy="0 0 0" />
      <geometry>
        <mesh
          filename="package://RobotNurse.URDF/meshes/w3.STL" />
      </geometry>
      <material
        name="">
        <color
          rgba="0.75294 0.75294 0.75294 1" />
      </material>
    </visual>
    <collision>
      <origin
        xyz="0 0 0"
        rpy="0 0 0" />
      <geometry>
        <mesh
          filename="package://RobotNurse.URDF/meshes/w3.STL" />
      </geometry>
    </collision>
  </link>
  <joint
    name="w3"
    type="continuous">
    <origin
      xyz="-0.2 0.25 0.08"
      rpy="2.97658962801217 0 3.14159265358979" />
    <parent
      link="Base" />
    <child
      link="w3" />
    <axis
      xyz="1 0 0" />
  </joint>
  <link
    name="w4">
    <inertial>
      <origin
        xyz="0.0745364696784733 0 0"
        rpy="0 0 0" />
      <mass
        value="6.77753430076086" />
      <inertia
        ixx="0.0532193232995393"
        ixy="-1.39685299760028E-19"
        ixz="9.07441870162449E-21"
        iyy="0.0380198317305351"
        iyz="0"
        izz="0.0380198317305351" />
    </inertial>
    <visual>
      <origin
        xyz="0 0 0"
        rpy="0 0 0" />
      <geometry>
        <mesh
          filename="package://RobotNurse.URDF/meshes/w4.STL" />
      </geometry>
      <material
        name="">
        <color
          rgba="0.752941176470588 0.752941176470588 0.752941176470588 1" />
      </material>
    </visual>
    <collision>
      <origin
        xyz="0 0 0"
        rpy="0 0 0" />
      <geometry>
        <mesh
          filename="package://RobotNurse.URDF/meshes/w4.STL" />
      </geometry>
    </collision>
  </link>
  <joint
    name="w4"
    type="continuous">
    <origin
      xyz="-0.2 0.25 0.08"
      rpy="2.97658962801217 0 3.14159265358979" />
    <parent
      link="Base" />
    <child
      link="w4" />
    <axis
      xyz="1 0 0" />
  </joint>
</robot>